Workbook

Sheet Data Set
C2: UIUC
B3: Master of Business Analytics (MSBA)
B5: Year | C5: Semester | D5: # Enrolled | E5: Avg/Year | F5: Growth Rate (%) | H5: Source Link: | J5: https://www.dmi.illinois.edu/stuenr/#class
B6: 2025 | C6: Fall | D6: 99 | E6: =AVERAGE(D6:D7) -> 111.5 | F6: =(E6/E8)-1 -> -0.034632035
C7: Spring | D7: 124
B8: 2024 | C8: Fall | D8: 129 | E8: =AVERAGE(D8:D9) -> 115.5 | F8: =(E8/E10)-1 -> 0.35882353
C9: Spring | D9: 102
B10: 2023 | C10: Fall | D10: 104 | E10: =AVERAGE(D10:D11) -> 85 | F10: =(E10/E12)-1 -> 0.12582781
C11: Spring | D11: 66
B12: 2022 | C12: Fall | D12: 99 | E12: =AVERAGE(D12:D13) -> 75.5 | F12: =(E12/E14)-1 -> 1.9038462
C13: Spring | D13: 52
B14: 2021 | C14: Fall | D14: 26 | E14: =AVERAGE(D14:D18) -> 26 | F14: --
C19: Iowa Tippie
B20: Master of Business Analytics (+iMSBA)
B22: Year | C22: Semester | D22: # Enrolled | E22: Avg/Year | F22: Growth Rate (%) | H22: Source Link: | J22: https://registrar.uiowa.edu/data-reports-and-requests
B23: 2025 | C23: Fall | D23: 308 | E23: =AVERAGE(D23:D24) -> 285 | F23: =(E23/E25)-1 -> 0.091954023
C24: Spring | D24: 262
B25: 2024 | C25: Fall | D25: 251 | E25: =AVERAGE(D25:D26) -> 261 | F25: =(E25/E27)-1 -> 1.3097345
C26: Spring | D26: 271
B27: 2023 | C27: Fall | D27: 113 | E27: =AVERAGE(D27:D28) -> 113 | F27: --
G35: After the launch of Online MSA in April, 2017
C36: UIUC (2010 - 2016) | L36: UIUC (2017 - 2025)
B37: Master of Science in Accountancy (MSA) | K37: Master of Science in Accountancy + iMSA
B39: Year | C39: Semester | D39: # Enrolled | E39: Avg/Year | F39: Growth Rate (%) | K39: Year | L39: Semester | M39: # Enrolled | N39: Avg/Year | O39: Growth Rate (%)
B40: 2016 | C40: Fall | D40: 153 | E40: =AVERAGE(D40:D41) -> 147 | F40: =(E40/E42)-1 -> 0.027972028 | K40: 2025 | L40: Fall | M40: =173+510+4+1 -> 688 | N40: =AVERAGE(M40:M41) -> 656 | O40: =(N40/N42)-1 -> 0.12908778
C41: Spring | D41: 141 | L41: Spring | M41: =119+453+4+1+47 -> 624
B42: 2015 | C42: Fall | D42: 143 | E42: =AVERAGE(D42:D43) -> 143 | F42: =(E42/E44)-1 -> 0 | K42: 2024 | L42: Fall | M42: =170+442+4+2 -> 618 | N42: =AVERAGE(M42:M43) -> 581 | O42: =(N42/N44)-1 -> 0.0375
C43: Spring | D43: 143 | L43: Spring | M43: =160+376+8 -> 544
B44: 2014 | C44: Fall | D44: 144 | E44: =AVERAGE(D44:D45) -> 143 | F44: =(E44/E46)-1 -> 0.028776978 | K44: 2023 | L44: Fall | M44: =162+383+4+14 -> 563 | N44: =AVERAGE(M44:M45) -> 560 | O44: =(N44/N46)-1 -> -0.16230366
C45: Spring | D45: 142 | L45: Spring | M45: =90+407+2+56+2 -> 557
B46: 2013 | C46: Fall | D46: 142 | E46: =AVERAGE(D46:D47) -> 139 | F46: =(E46/E48)-1 -> -0.034722222 | K46: 2022 | L46: Fall | M46: =150+468+3+7 -> 628 | N46: =AVERAGE(M46:M47) -> 668.5 | O46: =(N46/N48)-1 -> 0.0030007502
C47: Spring | D47: 136 | L47: Spring | M47: =190+514+1+4 -> 709
B48: 2012 | C48: Fall | D48: 142 | E48: =AVERAGE(D48:D49) -> 144 | F48: =(E48/E50)-1 -> 0.07063197 | K48: 2021 | L48: Fall | M48: =205+539+1+6 -> 751 | N48: =AVERAGE(M48:M49) -> 666.5 | O48: =(N48/N50)-1 -> 0.25992439
C49: Spring | D49: 146 | L49: Spring | M49: =56+503+23 -> 582
B50: 2011 | C50: Fall | D50: 136 | E50: =AVERAGE(D50:D51) -> 134.5 | F50: =(E50/E52)-1 -> 0.026717557 | K50: 2020 | L50: Fall | M50: =68+454+8 -> 530 | N50: =AVERAGE(M50:M51) -> 529 | O50: =(N50/N52)-1 -> 0.16519824
C51: Spring | D51: 133 | L51: Spring | M51: =116+330+82 -> 528
B52: 2010 | C52: Fall | D52: 137 | E52: =AVERAGE(D52:D53) -> 131 | F52: -- | K52: 2019 | L52: Fall | M52: =199+303 -> 502 | N52: =AVERAGE(M52:M53) -> 454 | O52: =(N52/N54)-1 -> 0.58188153
C53: Spring | D53: =121+4 -> 125 | L53: Spring | M53: =173+233 -> 406
K54: 2018 | L54: Fall | M54: =173+173 -> 346 | N54: =AVERAGE(M54:M55) -> 287 | O54: =(N54/N56)-1 -> 0.4137931
L55: Spring | M55: =122+87+19 -> 228
...

Sheet Summary
B2: ONLINE iMSBA ENROLLMENT PROJECTION
B3: Growth Model Based on MSA/iMSA & Iowa iMSBA Launch Impact
B5: EXECUTIVE SUMMARY
B7: Methodology:
B8: This projection blends UIUC's MSA/iMSA historical growth pattern with Iowa's iMSBA launch data to forecast UIUC Online iMSBA enrollment growth starting in 2026.
B11: KEY PROJECTIONS (2026-2035)
B13: Metric | C13: Value
B14: Starting Enrollment (2025) | C14: {=MSBA_Projections!C20} -> 111.5
B15: Projected Enrollment (2035) | C15: {=MSBA_Projections!C21} -> 928.48886
B16: Total Growth | C16: {=MSBA_Projections!C19} -> 7.3272543
B17: Net Student Addition | C17: {=MSBA_Projections!C22} -> 816.98886
B18: Average Annual Growth Rate | C18: {=MSBA_Projections!C23} -> 0.25593505
B19: Peak Annual Growth | C19: {=MSBA_Projections!C25} -> 210.04646
B20: Year of Peak Growth | C20: {=MSBA_Projections!C26} -> 2029
B22: GROWTH RATE COMPARISON: MSA/iMSA vs iMSBA
B24: Phase | C24: MSA/iMSA (Historical) | D24: iMSBA (Projected) | E24: Duration
B25: Launch Phase | C25: {=Assumptions!C29} -> 0.35519932 | D25: {=Assumptions!C51} -> 0.52802179 | E25: Years 1-4
B26: Maturity Phase | C26: {=Assumptions!C30} -> -0.040600972 | D26: {=Assumptions!D62} -> 0.02 | E26: Years 5-7
B27: Stabilization Phase | C27: {=Assumptions!C31} -> 0.12908778 | D27: {=Assumptions!C53} -> 0.12908778 | E27: Years 8-10
B29: KEY INSIGHTS
B31: 1. Launch Phase Impact:
B32: Blending MSA/iMSA (35.5%) and Iowa iMSBA (70.1%) growth rates yields 52.8% average annual growth in the first 4 years (2026-2029). Applying this pattern, iMSBA enrollment could reach 608 students by 2029.
B34: 2. Maturity Stabilization:
B35: MSA/iMSA growth slowed during maturity. iMSBA projections assume a minimum 2% growth during this phase (Years 5-7).
B37: 3. Long-term Outlook:
B38: By 2035, iMSBA enrollment could reach approximately 928 students, representing a 7.3x increase from the 2025 baseline.
B40: SCENARIO ANALYSIS
B42: The projections assume Online iMSBA follows a blended growth trajectory based on MSA/iMSA and Iowa iMSBA patterns. Actual results may vary based on:
B44: • Market conditions and competition
B45: • Marketing and recruitment efforts
B46: • Program capacity and resources
... B50: YEAR-BY-YEAR ENROLLMENT FORECAST
B52: Year | C52: Enrollment | D52: Growth Rate | E52: Net Addition
B53: {=MSBA_Projections!B5} -> 2025 | C53: {=MSBA_Projections!F5} -> 111.5 | D53: Baseline | E53: N/A
B54: {=MSBA_Projections!B6} -> 2026 | C54: {=MSBA_Projections!F6} -> 170.37443 | D54: {=MSBA_Projections!E6} -> 0.52802179 | E54: {=MSBA_Projections!G6} -> 58.87443
B55: {=MSBA_Projections!B7} -> 2027 | C55: {=MSBA_Projections!F7} -> 260.33584 | D55: {=MSBA_Projections!E7} -> 0.52802179 | E55: {=MSBA_Projections!G7} -> 89.961412
B56: {=MSBA_Projections!B8} -> 2028 | C56: {=MSBA_Projections!F8} -> 397.79884 | D56: {=MSBA_Projections!E8} -> 0.52802179 | E56: {=MSBA_Projections!G8} -> 137.463
B57: {=MSBA_Projections!B9} -> 2029 | C57: {=MSBA_Projections!F9} -> 607.84529 | D57: {=MSBA_Projections!E9} -> 0.52802179 | E57: {=MSBA_Projections!G9} -> 210.04646
B58: {=MSBA_Projections!B10} -> 2030 | C58: {=MSBA_Projections!F10} -> 620.0022 | D58: {=MSBA_Projections!E10} -> 0.02 | E58: {=MSBA_Projections!G10} -> 12.156906
B59: {=MSBA_Projections!B11} -> 2031 | C59: {=MSBA_Projections!F11} -> 632.40224 | D59: {=MSBA_Projections!E11} -> 0.02 | E59: {=MSBA_Projections!G11} -> 12.400044
...

Sheet Assumptions
B2: ENROLLMENT PROJECTION ASSUMPTIONS
B4: MSA Program Growth (Pre-Online Era: 2010-2016) | F4: IOWA iMSBA COMPARISON
B5: Year | C5: Avg Enrollment | D5: YoY Growth | F5: Year | G5: Enrollment | H5: YoY Growth
B6: 2010 | C6: 131 | F6: 2023 | G6: 113
B7: 2011 | C7: 134.5 | D7: =(C7/C6)-1 -> 0.026717557 | F7: 2024 | G7: 261 | H7: =(G7/G6)-1 -> 1.3097345
B8: 2012 | C8: 144 | D8: =(C8/C7)-1 -> 0.07063197 | F8: 2025 | G8: 285 | H8: =(G8/G7)-1 -> 0.091954023
B9: 2013 | C9: 139 | D9: =(C9/C8)-1 -> -0.034722222
B10: 2014 | C10: 143 | D10: =(C10/C9)-1 -> 0.028776978 | F10: Note: Iowa launched online MSBA (iMSBA) in 2023
B11: 2015 | C11: 143 | D11: =(C11/C10)-1 -> 0 | F11: Avg Growth Rate (Iowa iMSBA) | G11: =AVERAGE(H7:H8) -> 0.70084427
B12: 2016 | C12: 147 | D12: =(C12/C11)-1 -> 0.027972028
B13: Average Growth Rate (2011-2016) | C13: =AVERAGE(D7:D12) -> 0.019896052
B15: MSA + iMSA Growth (Post-Online Launch: 2017-2025)
B16: Year | C16: Avg Enrollment | D16: YoY Growth
B17: 2017 | C17: 203
B18: 2018 | C18: 287 | D18: =(C18/C17)-1 -> 0.4137931
B19: 2019 | C19: 454 | D19: =(C19/C18)-1 -> 0.58188153
B20: 2020 | C20: 529 | D20: =(C20/C19)-1 -> 0.16519824
B21: 2021 | C21: 666.5 | D21: =(C21/C20)-1 -> 0.25992439
B22: 2022 | C22: 668.5 | D22: =(C22/C21)-1 -> 0.0030007502
B23: 2023 | C23: 560 | D23: =(C23/C22)-1 -> -0.16230366
B24: 2024 | C24: 581 | D24: =(C24/C23)-1 -> 0.0375
B25: 2025 | C25: 656 | D25: =(C25/C24)-1 -> 0.12908778
B28: Growth Phase Analysis:
B29: Launch Phase (2017-2020) | C29: =AVERAGE(D18:D21) -> 0.35519932
B30: Maturity Phase (2021-2023) | C30: =AVERAGE(D22:D24) -> -0.040600972
B31: Stabilization Phase (2024+) | C31: =AVERAGE(D25) -> 0.12908778
B34: UIUC MSBA Program Baseline (2021-2025)
B35: Year | C35: Avg Enrollment | D35: YoY Growth
B36: 2021 | C36: 26
B37: 2022 | C37: 75.5 | D37: =(C37/C36)-1 -> 1.9038462
B38: 2023 | C38: 85 | D38: =(C38/C37)-1 -> 0.12582781
B39: 2024 | C39: 115.5 | D39: =(C39/C38)-1 -> 0.35882353
B40: 2025 | C40: 111.5 | D40: =(C40/C39)-1 -> -0.034632035
B41: Average Growth Rate (2022-2025) | C41: =AVERAGE(D37:D40) -> 0.58846637
B44: PROJECTION SCENARIOS FOR ONLINE iMSBA
B46: Scenario Assumptions:
B47: Launch Year for Online iMSBA | C47: 2026
B48: Projection Period (Years) | C48: 10
B50: Growth Rates to Apply:
B51: Launch Phase (Years 1-4) | C51: =(C29+G11)/2 -> 0.52802179 | D51: Blend of MSA/iMSA & Iowa iMSBA growth
...

Sheet MSBA_Projections
B2: ONLINE iMSBA ENROLLMENT PROJECTIONS (2026-2035)
B4: Year | C4: Years Since Launch | D4: Growth Phase | E4: Applied Growth Rate | F4: Projected Enrollment | G4: YoY Change
B5: 2025 | C5: 0 | D5: Baseline (Pre-Online) | E5: N/A | F5: {=Assumptions!C40} -> 111.5 | G5: N/A
B6: 2026 | C6: 1 | D6: Launch Phase | E6: {=Assumptions!C51} -> 0.52802179 | F6: =F5*(1+E6) -> 170.37443 | G6: =F6-F5 -> 58.87443
B7: 2027 | C7: 2 | D7: Launch Phase | E7: {=Assumptions!C51} -> 0.52802179 | F7: =F6*(1+E7) -> 260.33584 | G7: =F7-F6 -> 89.961412
B8: 2028 | C8: 3 | D8: Launch Phase | E8: {=Assumptions!C51} -> 0.52802179 | F8: =F7*(1+E8) -> 397.79884 | G8: =F8-F7 -> 137.463
B9: 2029 | C9: 4 | D9: Launch Phase | E9: {=Assumptions!C51} -> 0.52802179 | F9: =F8*(1+E9) -> 607.84529 | G9: =F9-F8 -> 210.04646
B10: 2030 | C10: 5 | D10: Maturity Phase | E10: {=Assumptions!D62} -> 0.02 | F10: =F9*(1+E10) -> 620.0022 | G10: =F10-F9 -> 12.156906
B11: 2031 | C11: 6 | D11: Maturity Phase | E11: {=Assumptions!D62} -> 0.02 | F11: =F10*(1+E11) -> 632.40224 | G11: =F11-F10 -> 12.400044
B12: 2032 | C12: 7 | D12: Maturity Phase | E12: {=Assumptions!D62} -> 0.02 | F12: =F11*(1+E12) -> 645.05029 | G12: =F12-F11 -> 12.648045
B13: 2033 | C13: 8 | D13: Stabilization | E13: {=Assumptions!C53} -> 0.12908778 | F13: =F12*(1+E13) -> 728.3184 | G13: =F13-F12 -> 83.26811
B14: 2034 | C14: 9 | D14: Stabilization | E14: {=Assumptions!C53} -> 0.12908778 | F14: =F13*(1+E14) -> 822.3354 | G14: =F14-F13 -> 94.017005
B15: 2035 | C15: 10 | D15: Stabilization | E15: {=Assumptions!C53} -> 0.12908778 | F15: =F14*(1+E15) -> 928.48886 | G15: =F15-F14 -> 106.15345
B17: PROJECTION SUMMARY
B19: Total Growth (2025-2035) | C19: =F15/F5-1 -> 7.3272543
B20: Starting Enrollment (2025) | C20: {=F5} -> 111.5
B21: Ending Enrollment (2035) | C21: {=F15} -> 928.48886
B22: Total Student Growth | C22: =F15-F5 -> 816.98886
B23: Average Annual Growth Rate | C23: =AVERAGE(E6:E15) -> 0.25593505
B25: Peak Annual Addition | C25: =MAX(G6:G15) -> 210.04646
B26: Year of Peak Addition | C26: {=INDEX(B6:B15,MATCH(MAX(G6:G15),G6:G15,0))} -> 2029

Sheet Scenarios
B2: ONLINE iMSBA ENROLLMENT SCENARIOS (2026-2035)
B3: Comparing Best Case, Base Case, and Worst Case Growth Projections
B5: Year | C5: Best Case | D5: Base Case | E5: Worst Case | F5: Best-Worst Range
B6: 2025 | C6: {=Assumptions!C40} -> 111.5 | D6: {=Assumptions!C40} -> 111.5 | E6: {=Assumptions!C40} -> 111.5 | F6: 0
B7: 2026 | C7: =C6*(1+Assumptions!C61) -> 182.14932 | D7: =D6*(1+Assumptions!C62) -> 170.37443 | E7: =E6*(1+Assumptions!C63) -> 152.7121 | F7: =C7-E7 -> 29.437215
B8: 2027 | C8: =C7*(1+Assumptions!C61) -> 297.56389 | D8: =D7*(1+Assumptions!C62) -> 260.33584 | E8: =E7*(1+Assumptions!C63) -> 209.15682 | F8: =C8-E8 -> 88.407063
B9: 2028 | C9: =C8*(1+Assumptions!C61) -> 486.10814 | D9: =D8*(1+Assumptions!C62) -> 397.79884 | E9: =E8*(1+Assumptions!C63) -> 286.46437 | F9: =C9-E9 -> 199.64377
B10: 2029 | C10: =C9*(1+Assumptions!C61) -> 794.11898 | D10: =D9*(1+Assumptions!C62) -> 607.84529 | E10: =E9*(1+Assumptions!C63) -> 392.34598 | F10: =C10-E10 -> 401.773
B11: 2030 | C11: =C10*(1+Assumptions!D61) -> 833.82493 | D11: =D10*(1+Assumptions!D62) -> 620.0022 | E11: =E10*(1+Assumptions!D63) -> 392.34598 | F11: =C11-E11 -> 441.47895
B12: 2031 | C12: =C11*(1+Assumptions!D61) -> 875.51617 | D12: =D11*(1+Assumptions!D62) -> 632.40224 | E12: =E11*(1+Assumptions!D63) -> 392.34598 | F12: =C12-E12 -> 483.17019
B13: 2032 | C13: =C12*(1+Assumptions!D61) -> 919.29198 | D13: =D12*(1+Assumptions!D62) -> 645.05029 | E13: =E12*(1+Assumptions!D63) -> 392.34598 | F13: =C13-E13 -> 526.946
B14: 2033 | C14: =C13*(1+Assumptions!E61) -> 1061.6952 | D14: =D13*(1+Assumptions!E62) -> 728.3184 | E14: =E13*(1+Assumptions!E63) -> 427.79893 | F14: =C14-E14 -> 633.89629
B15: 2034 | C15: =C14*(1+Assumptions!E61) -> 1226.1575 | D15: =D14*(1+Assumptions!E62) -> 822.3354 | E15: =E14*(1+Assumptions!E63) -> 466.45546 | F15: =C15-E15 -> 759.70201
B16: 2035 | C16: =C15*(1+Assumptions!E61) -> 1416.0958 | D16: =D15*(1+Assumptions!E62) -> 928.48886 | E16: =E15*(1+Assumptions!E63) -> 508.60505 | F16: =C16-E16 -> 907.49075
B18: SCENARIO COMPARISON SUMMARY
B20: Metric | C20: Best Case | D20: Base Case | E20: Worst Case
B21: 2035 Enrollment | C21: {=C16} -> 1416.0958 | D21: {=D16} -> 928.48886 | E21: {=E16} -> 508.60505
B22: Total Growth (2025-2035) | C22: =(C16/C6)-1 -> 11.700411 | D22: =(D16/D6)-1 -> 7.3272543 | E22: =(E16/E6)-1 -> 3.5614802
B23: Net Student Addition | C23: =C16-C6 -> 1304.5958 | D23: =D16-D6 -> 816.98886 | E23: =E16-E6 -> 397.10505
B24: Avg Annual Growth Rate | C24: =(C16/C6)^(1/10)-1 -> 0.28938252 | D24: =(D16/D6)^(1/10)-1 -> 0.23609026 | E24: =(E16/E6)^(1/10)-1 -> 0.16388636
B25: 2029 Enrollment (End Launch) | C25: {=C10} -> 794.11898 | D25: {=D10} -> 607.84529 | E25: {=E10} -> 392.34598
B27: KEY INSIGHTS:
B29: Enrollment Range by 2035: | C29: =E16&" - "&C16&" students" -> 508.605046631259 - 1416.09579961303 students
B30: Variance between scenarios: | C30: {=F16} -> 907.49075 | D30: students difference
B32: Most Likely Range: | C32: =CONCATENATE("Base to Best Case (",TEXT(D16,"#,##0")," - ",TEXT(C16,"#,##0")," students)") -> Base to Best Case (928 - 1,416 students)
